[2023-12-24T16:08:58.986+0000] {taskinstance.py:1171} INFO - Dependencies all met for <TaskInstance: example.fetching_data manual__2023-12-24T16:08:58.209865+00:00 [queued]>
[2023-12-24T16:08:58.992+0000] {taskinstance.py:1171} INFO - Dependencies all met for <TaskInstance: example.fetching_data manual__2023-12-24T16:08:58.209865+00:00 [queued]>
[2023-12-24T16:08:58.992+0000] {taskinstance.py:1368} INFO - 
--------------------------------------------------------------------------------
[2023-12-24T16:08:58.992+0000] {taskinstance.py:1369} INFO - Starting attempt 1 of 1
[2023-12-24T16:08:58.992+0000] {taskinstance.py:1370} INFO - 
--------------------------------------------------------------------------------
[2023-12-24T16:08:58.998+0000] {taskinstance.py:1389} INFO - Executing <Task(PythonOperator): fetching_data> on 2023-12-24 16:08:58.209865+00:00
[2023-12-24T16:08:59.003+0000] {standard_task_runner.py:52} INFO - Started process 632 to run task
[2023-12-24T16:08:59.006+0000] {standard_task_runner.py:79} INFO - Running: ['***', 'tasks', 'run', 'example', 'fetching_data', 'manual__2023-12-24T16:08:58.209865+00:00', '--job-id', '17', '--raw', '--subdir', 'DAGS_FOLDER/P2M3_saepul_hilal_DAG.py', '--cfg-path', '/tmp/tmpz1_jubf3', '--error-file', '/tmp/tmpfrzotv08']
[2023-12-24T16:08:59.007+0000] {standard_task_runner.py:80} INFO - Job 17: Subtask fetching_data
[2023-12-24T16:08:59.046+0000] {task_command.py:371} INFO - Running <TaskInstance: example.fetching_data manual__2023-12-24T16:08:58.209865+00:00 [running]> on host fb95896ee755
[2023-12-24T16:08:59.098+0000] {taskinstance.py:1583} INFO - Exporting the following env vars:
AIRFLOW_CTX_DAG_OWNER=saepul
AIRFLOW_CTX_DAG_ID=example
AIRFLOW_CTX_TASK_ID=fetching_data
AIRFLOW_CTX_EXECUTION_DATE=2023-12-24T16:08:58.209865+00:00
AIRFLOW_CTX_TRY_NUMBER=1
AIRFLOW_CTX_DAG_RUN_ID=manual__2023-12-24T16:08:58.209865+00:00
[2023-12-24T16:08:59.101+0000] {taskinstance.py:1902} ERROR - Task failed with exception
Traceback (most recent call last):
  File "/home/airflow/.local/lib/python3.7/site-packages/sqlalchemy/engine/base.py", line 3243, in _wrap_pool_connect
    return fn()
  File "/home/airflow/.local/lib/python3.7/site-packages/sqlalchemy/pool/base.py", line 310, in connect
    return _ConnectionFairy._checkout(self)
  File "/home/airflow/.local/lib/python3.7/site-packages/sqlalchemy/pool/base.py", line 868, in _checkout
    fairy = _ConnectionRecord.checkout(pool)
  File "/home/airflow/.local/lib/python3.7/site-packages/sqlalchemy/pool/base.py", line 476, in checkout
    rec = pool._do_get()
  File "/home/airflow/.local/lib/python3.7/site-packages/sqlalchemy/pool/impl.py", line 146, in _do_get
    self._dec_overflow()
  File "/home/airflow/.local/lib/python3.7/site-packages/sqlalchemy/util/langhelpers.py", line 72, in __exit__
    with_traceback=exc_tb,
  File "/home/airflow/.local/lib/python3.7/site-packages/sqlalchemy/util/compat.py", line 207, in raise_
    raise exception
  File "/home/airflow/.local/lib/python3.7/site-packages/sqlalchemy/pool/impl.py", line 143, in _do_get
    return self._create_connection()
  File "/home/airflow/.local/lib/python3.7/site-packages/sqlalchemy/pool/base.py", line 256, in _create_connection
    return _ConnectionRecord(self)
  File "/home/airflow/.local/lib/python3.7/site-packages/sqlalchemy/pool/base.py", line 371, in __init__
    self.__connect()
  File "/home/airflow/.local/lib/python3.7/site-packages/sqlalchemy/pool/base.py", line 666, in __connect
    pool.logger.debug("Error on connect(): %s", e)
  File "/home/airflow/.local/lib/python3.7/site-packages/sqlalchemy/util/langhelpers.py", line 72, in __exit__
    with_traceback=exc_tb,
  File "/home/airflow/.local/lib/python3.7/site-packages/sqlalchemy/util/compat.py", line 207, in raise_
    raise exception
  File "/home/airflow/.local/lib/python3.7/site-packages/sqlalchemy/pool/base.py", line 661, in __connect
    self.dbapi_connection = connection = pool._invoke_creator(self)
  File "/home/airflow/.local/lib/python3.7/site-packages/sqlalchemy/engine/create.py", line 590, in connect
    return dialect.connect(*cargs, **cparams)
  File "/home/airflow/.local/lib/python3.7/site-packages/sqlalchemy/engine/default.py", line 584, in connect
    return self.dbapi.connect(*cargs, **cparams)
  File "/home/airflow/.local/lib/python3.7/site-packages/psycopg2/__init__.py", line 122, in connect
    conn = _connect(dsn, connection_factory=connection_factory, **kwasync)
psycopg2.OperationalError: FATAL:  database "milestone3" does not exist


The above exception was the direct cause of the following exception:

Traceback (most recent call last):
  File "/home/airflow/.local/lib/python3.7/site-packages/airflow/operators/python.py", line 171, in execute
    return_value = self.execute_callable()
  File "/home/airflow/.local/lib/python3.7/site-packages/airflow/operators/python.py", line 189, in execute_callable
    return self.python_callable(*self.op_args, **self.op_kwargs)
  File "/opt/airflow/dags/P2M3_saepul_hilal_DAG.py", line 17, in ambil_data
    conn = engine.connect()
  File "/home/airflow/.local/lib/python3.7/site-packages/sqlalchemy/engine/base.py", line 3197, in connect
    return self._connection_cls(self, close_with_result=close_with_result)
  File "/home/airflow/.local/lib/python3.7/site-packages/sqlalchemy/engine/base.py", line 96, in __init__
    else engine.raw_connection()
  File "/home/airflow/.local/lib/python3.7/site-packages/sqlalchemy/engine/base.py", line 3276, in raw_connection
    return self._wrap_pool_connect(self.pool.connect, _connection)
  File "/home/airflow/.local/lib/python3.7/site-packages/sqlalchemy/engine/base.py", line 3247, in _wrap_pool_connect
    e, dialect, self
  File "/home/airflow/.local/lib/python3.7/site-packages/sqlalchemy/engine/base.py", line 2101, in _handle_dbapi_exception_noconnection
    sqlalchemy_exception, with_traceback=exc_info[2], from_=e
  File "/home/airflow/.local/lib/python3.7/site-packages/sqlalchemy/util/compat.py", line 207, in raise_
    raise exception
  File "/home/airflow/.local/lib/python3.7/site-packages/sqlalchemy/engine/base.py", line 3243, in _wrap_pool_connect
    return fn()
  File "/home/airflow/.local/lib/python3.7/site-packages/sqlalchemy/pool/base.py", line 310, in connect
    return _ConnectionFairy._checkout(self)
  File "/home/airflow/.local/lib/python3.7/site-packages/sqlalchemy/pool/base.py", line 868, in _checkout
    fairy = _ConnectionRecord.checkout(pool)
  File "/home/airflow/.local/lib/python3.7/site-packages/sqlalchemy/pool/base.py", line 476, in checkout
    rec = pool._do_get()
  File "/home/airflow/.local/lib/python3.7/site-packages/sqlalchemy/pool/impl.py", line 146, in _do_get
    self._dec_overflow()
  File "/home/airflow/.local/lib/python3.7/site-packages/sqlalchemy/util/langhelpers.py", line 72, in __exit__
    with_traceback=exc_tb,
  File "/home/airflow/.local/lib/python3.7/site-packages/sqlalchemy/util/compat.py", line 207, in raise_
    raise exception
  File "/home/airflow/.local/lib/python3.7/site-packages/sqlalchemy/pool/impl.py", line 143, in _do_get
    return self._create_connection()
  File "/home/airflow/.local/lib/python3.7/site-packages/sqlalchemy/pool/base.py", line 256, in _create_connection
    return _ConnectionRecord(self)
  File "/home/airflow/.local/lib/python3.7/site-packages/sqlalchemy/pool/base.py", line 371, in __init__
    self.__connect()
  File "/home/airflow/.local/lib/python3.7/site-packages/sqlalchemy/pool/base.py", line 666, in __connect
    pool.logger.debug("Error on connect(): %s", e)
  File "/home/airflow/.local/lib/python3.7/site-packages/sqlalchemy/util/langhelpers.py", line 72, in __exit__
    with_traceback=exc_tb,
  File "/home/airflow/.local/lib/python3.7/site-packages/sqlalchemy/util/compat.py", line 207, in raise_
    raise exception
  File "/home/airflow/.local/lib/python3.7/site-packages/sqlalchemy/pool/base.py", line 661, in __connect
    self.dbapi_connection = connection = pool._invoke_creator(self)
  File "/home/airflow/.local/lib/python3.7/site-packages/sqlalchemy/engine/create.py", line 590, in connect
    return dialect.connect(*cargs, **cparams)
  File "/home/airflow/.local/lib/python3.7/site-packages/sqlalchemy/engine/default.py", line 584, in connect
    return self.dbapi.connect(*cargs, **cparams)
  File "/home/airflow/.local/lib/python3.7/site-packages/psycopg2/__init__.py", line 122, in connect
    conn = _connect(dsn, connection_factory=connection_factory, **kwasync)
sqlalchemy.exc.OperationalError: (psycopg2.OperationalError) FATAL:  database "milestone3" does not exist

(Background on this error at: https://sqlalche.me/e/14/e3q8)
[2023-12-24T16:08:59.110+0000] {taskinstance.py:1412} INFO - Marking task as FAILED. dag_id=example, task_id=fetching_data, execution_date=20231224T160858, start_date=20231224T160858, end_date=20231224T160859
[2023-12-24T16:08:59.118+0000] {standard_task_runner.py:97} ERROR - Failed to execute job 17 for task fetching_data ((psycopg2.OperationalError) FATAL:  database "milestone3" does not exist

(Background on this error at: https://sqlalche.me/e/14/e3q8); 632)
[2023-12-24T16:08:59.142+0000] {local_task_job.py:156} INFO - Task exited with return code 1
[2023-12-24T16:08:59.158+0000] {local_task_job.py:279} INFO - 0 downstream tasks scheduled from follow-on schedule check
