[2023-12-25T07:04:47.225+0000] {taskinstance.py:1171} INFO - Dependencies all met for <TaskInstance: example.edit_data manual__2023-12-25T07:04:45.153116+00:00 [queued]>
[2023-12-25T07:04:47.229+0000] {taskinstance.py:1171} INFO - Dependencies all met for <TaskInstance: example.edit_data manual__2023-12-25T07:04:45.153116+00:00 [queued]>
[2023-12-25T07:04:47.229+0000] {taskinstance.py:1368} INFO - 
--------------------------------------------------------------------------------
[2023-12-25T07:04:47.230+0000] {taskinstance.py:1369} INFO - Starting attempt 1 of 1
[2023-12-25T07:04:47.230+0000] {taskinstance.py:1370} INFO - 
--------------------------------------------------------------------------------
[2023-12-25T07:04:47.236+0000] {taskinstance.py:1389} INFO - Executing <Task(PythonOperator): edit_data> on 2023-12-25 07:04:45.153116+00:00
[2023-12-25T07:04:47.239+0000] {standard_task_runner.py:52} INFO - Started process 573 to run task
[2023-12-25T07:04:47.241+0000] {standard_task_runner.py:79} INFO - Running: ['***', 'tasks', 'run', 'example', 'edit_data', 'manual__2023-12-25T07:04:45.153116+00:00', '--job-id', '63', '--raw', '--subdir', 'DAGS_FOLDER/P2M3_saepul_hilal_DAG.py', '--cfg-path', '/tmp/tmpndwcq8y1', '--error-file', '/tmp/tmp74u1glsf']
[2023-12-25T07:04:47.242+0000] {standard_task_runner.py:80} INFO - Job 63: Subtask edit_data
[2023-12-25T07:04:47.273+0000] {task_command.py:371} INFO - Running <TaskInstance: example.edit_data manual__2023-12-25T07:04:45.153116+00:00 [running]> on host fb95896ee755
[2023-12-25T07:04:47.307+0000] {taskinstance.py:1583} INFO - Exporting the following env vars:
AIRFLOW_CTX_DAG_OWNER=Saepul
AIRFLOW_CTX_DAG_ID=example
AIRFLOW_CTX_TASK_ID=edit_data
AIRFLOW_CTX_EXECUTION_DATE=2023-12-25T07:04:45.153116+00:00
AIRFLOW_CTX_TRY_NUMBER=1
AIRFLOW_CTX_DAG_RUN_ID=manual__2023-12-25T07:04:45.153116+00:00
[2023-12-25T07:04:47.316+0000] {taskinstance.py:1902} ERROR - Task failed with exception
Traceback (most recent call last):
  File "/home/airflow/.local/lib/python3.7/site-packages/pandas/core/indexes/base.py", line 3361, in get_loc
    return self._engine.get_loc(casted_key)
  File "pandas/_libs/index.pyx", line 76, in pandas._libs.index.IndexEngine.get_loc
  File "pandas/_libs/index.pyx", line 108, in pandas._libs.index.IndexEngine.get_loc
  File "pandas/_libs/hashtable_class_helper.pxi", line 5198, in pandas._libs.hashtable.PyObjectHashTable.get_item
  File "pandas/_libs/hashtable_class_helper.pxi", line 5206, in pandas._libs.hashtable.PyObjectHashTable.get_item
KeyError: 'price'

The above exception was the direct cause of the following exception:

Traceback (most recent call last):
  File "/home/airflow/.local/lib/python3.7/site-packages/airflow/operators/python.py", line 171, in execute
    return_value = self.execute_callable()
  File "/home/airflow/.local/lib/python3.7/site-packages/airflow/operators/python.py", line 189, in execute_callable
    return self.python_callable(*self.op_args, **self.op_kwargs)
  File "/opt/airflow/dags/P2M3_saepul_hilal_DAG.py", line 29, in processing
    df = df[df['price']<=tres]
  File "/home/airflow/.local/lib/python3.7/site-packages/pandas/core/frame.py", line 3458, in __getitem__
    indexer = self.columns.get_loc(key)
  File "/home/airflow/.local/lib/python3.7/site-packages/pandas/core/indexes/base.py", line 3363, in get_loc
    raise KeyError(key) from err
KeyError: 'price'
[2023-12-25T07:04:47.324+0000] {taskinstance.py:1412} INFO - Marking task as FAILED. dag_id=example, task_id=edit_data, execution_date=20231225T070445, start_date=20231225T070447, end_date=20231225T070447
[2023-12-25T07:04:47.329+0000] {standard_task_runner.py:97} ERROR - Failed to execute job 63 for task edit_data ('price'; 573)
[2023-12-25T07:04:47.378+0000] {local_task_job.py:156} INFO - Task exited with return code 1
[2023-12-25T07:04:47.395+0000] {local_task_job.py:279} INFO - 0 downstream tasks scheduled from follow-on schedule check
