[2023-12-24T16:17:56.940+0000] {taskinstance.py:1171} INFO - Dependencies all met for <TaskInstance: example.fetching_data manual__2023-12-24T16:17:56.043351+00:00 [queued]>
[2023-12-24T16:17:56.945+0000] {taskinstance.py:1171} INFO - Dependencies all met for <TaskInstance: example.fetching_data manual__2023-12-24T16:17:56.043351+00:00 [queued]>
[2023-12-24T16:17:56.945+0000] {taskinstance.py:1368} INFO - 
--------------------------------------------------------------------------------
[2023-12-24T16:17:56.945+0000] {taskinstance.py:1369} INFO - Starting attempt 1 of 1
[2023-12-24T16:17:56.945+0000] {taskinstance.py:1370} INFO - 
--------------------------------------------------------------------------------
[2023-12-24T16:17:56.952+0000] {taskinstance.py:1389} INFO - Executing <Task(PythonOperator): fetching_data> on 2023-12-24 16:17:56.043351+00:00
[2023-12-24T16:17:56.959+0000] {standard_task_runner.py:52} INFO - Started process 770 to run task
[2023-12-24T16:17:56.962+0000] {standard_task_runner.py:79} INFO - Running: ['***', 'tasks', 'run', 'example', 'fetching_data', 'manual__2023-12-24T16:17:56.043351+00:00', '--job-id', '23', '--raw', '--subdir', 'DAGS_FOLDER/P2M3_saepul_hilal_DAG.py', '--cfg-path', '/tmp/tmp1_khtblx', '--error-file', '/tmp/tmp2pt_k3ss']
[2023-12-24T16:17:56.963+0000] {standard_task_runner.py:80} INFO - Job 23: Subtask fetching_data
[2023-12-24T16:17:57.003+0000] {task_command.py:371} INFO - Running <TaskInstance: example.fetching_data manual__2023-12-24T16:17:56.043351+00:00 [running]> on host fb95896ee755
[2023-12-24T16:17:57.058+0000] {taskinstance.py:1583} INFO - Exporting the following env vars:
AIRFLOW_CTX_DAG_OWNER=saepul
AIRFLOW_CTX_DAG_ID=example
AIRFLOW_CTX_TASK_ID=fetching_data
AIRFLOW_CTX_EXECUTION_DATE=2023-12-24T16:17:56.043351+00:00
AIRFLOW_CTX_TRY_NUMBER=1
AIRFLOW_CTX_DAG_RUN_ID=manual__2023-12-24T16:17:56.043351+00:00
[2023-12-24T16:17:57.060+0000] {taskinstance.py:1902} ERROR - Task failed with exception
Traceback (most recent call last):
  File "/home/airflow/.local/lib/python3.7/site-packages/airflow/operators/python.py", line 171, in execute
    return_value = self.execute_callable()
  File "/home/airflow/.local/lib/python3.7/site-packages/airflow/operators/python.py", line 189, in execute_callable
    return self.python_callable(*self.op_args, **self.op_kwargs)
  File "/opt/airflow/dags/P2M3_saepul_hilal_DAG.py", line 18, in ambil_data
    conn=db.connect(conn_string)
  File "/home/airflow/.local/lib/python3.7/site-packages/psycopg2/__init__.py", line 122, in connect
    conn = _connect(dsn, connection_factory=connection_factory, **kwasync)
psycopg2.OperationalError: could not connect to server: Connection refused
	Is the server running on host "localhost" (127.0.0.1) and accepting
	TCP/IP connections on port 5432?
could not connect to server: Cannot assign requested address
	Is the server running on host "localhost" (::1) and accepting
	TCP/IP connections on port 5432?

[2023-12-24T16:17:57.066+0000] {taskinstance.py:1412} INFO - Marking task as FAILED. dag_id=example, task_id=fetching_data, execution_date=20231224T161756, start_date=20231224T161756, end_date=20231224T161757
[2023-12-24T16:17:57.071+0000] {standard_task_runner.py:97} ERROR - Failed to execute job 23 for task fetching_data (could not connect to server: Connection refused
	Is the server running on host "localhost" (127.0.0.1) and accepting
	TCP/IP connections on port 5432?
could not connect to server: Cannot assign requested address
	Is the server running on host "localhost" (::1) and accepting
	TCP/IP connections on port 5432?
; 770)
[2023-12-24T16:17:57.097+0000] {local_task_job.py:156} INFO - Task exited with return code 1
[2023-12-24T16:17:57.114+0000] {local_task_job.py:279} INFO - 0 downstream tasks scheduled from follow-on schedule check
