[2023-12-24T17:08:45.047+0000] {taskinstance.py:1171} INFO - Dependencies all met for <TaskInstance: example.fetching_data manual__2023-12-24T17:08:44.188070+00:00 [queued]>
[2023-12-24T17:08:45.051+0000] {taskinstance.py:1171} INFO - Dependencies all met for <TaskInstance: example.fetching_data manual__2023-12-24T17:08:44.188070+00:00 [queued]>
[2023-12-24T17:08:45.051+0000] {taskinstance.py:1368} INFO - 
--------------------------------------------------------------------------------
[2023-12-24T17:08:45.052+0000] {taskinstance.py:1369} INFO - Starting attempt 1 of 1
[2023-12-24T17:08:45.052+0000] {taskinstance.py:1370} INFO - 
--------------------------------------------------------------------------------
[2023-12-24T17:08:45.058+0000] {taskinstance.py:1389} INFO - Executing <Task(PythonOperator): fetching_data> on 2023-12-24 17:08:44.188070+00:00
[2023-12-24T17:08:45.064+0000] {standard_task_runner.py:52} INFO - Started process 224 to run task
[2023-12-24T17:08:45.067+0000] {standard_task_runner.py:79} INFO - Running: ['***', 'tasks', 'run', 'example', 'fetching_data', 'manual__2023-12-24T17:08:44.188070+00:00', '--job-id', '54', '--raw', '--subdir', 'DAGS_FOLDER/P2M3_saepul_hilal_DAG.py', '--cfg-path', '/tmp/tmp4hl98a2c', '--error-file', '/tmp/tmp_bylv8sf']
[2023-12-24T17:08:45.068+0000] {standard_task_runner.py:80} INFO - Job 54: Subtask fetching_data
[2023-12-24T17:08:45.115+0000] {task_command.py:371} INFO - Running <TaskInstance: example.fetching_data manual__2023-12-24T17:08:44.188070+00:00 [running]> on host fb95896ee755
[2023-12-24T17:08:45.156+0000] {taskinstance.py:1583} INFO - Exporting the following env vars:
AIRFLOW_CTX_DAG_OWNER=Rafif
AIRFLOW_CTX_DAG_ID=example
AIRFLOW_CTX_TASK_ID=fetching_data
AIRFLOW_CTX_EXECUTION_DATE=2023-12-24T17:08:44.188070+00:00
AIRFLOW_CTX_TRY_NUMBER=1
AIRFLOW_CTX_DAG_RUN_ID=manual__2023-12-24T17:08:44.188070+00:00
[2023-12-24T17:08:45.162+0000] {taskinstance.py:1902} ERROR - Task failed with exception
Traceback (most recent call last):
  File "/home/airflow/.local/lib/python3.7/site-packages/sqlalchemy/engine/base.py", line 1803, in _execute_context
    cursor, statement, parameters, context
  File "/home/airflow/.local/lib/python3.7/site-packages/sqlalchemy/engine/default.py", line 719, in do_execute
    cursor.execute(statement, parameters)
psycopg2.errors.UndefinedTable: relation "car_assignment" does not exist
LINE 1: select * from car_assignment
                      ^


The above exception was the direct cause of the following exception:

Traceback (most recent call last):
  File "/home/airflow/.local/lib/python3.7/site-packages/airflow/operators/python.py", line 171, in execute
    return_value = self.execute_callable()
  File "/home/airflow/.local/lib/python3.7/site-packages/airflow/operators/python.py", line 189, in execute_callable
    return self.python_callable(*self.op_args, **self.op_kwargs)
  File "/opt/airflow/dags/P2M3_saepul_hilal_DAG.py", line 17, in ambil_data
    df = pd.read_sql_query("select * from car_assignment", conn)
  File "/home/airflow/.local/lib/python3.7/site-packages/pandas/io/sql.py", line 443, in read_sql_query
    dtype=dtype,
  File "/home/airflow/.local/lib/python3.7/site-packages/pandas/io/sql.py", line 1579, in read_query
    result = self.execute(*args)
  File "/home/airflow/.local/lib/python3.7/site-packages/pandas/io/sql.py", line 1424, in execute
    return self.connectable.execution_options().execute(*args, **kwargs)
  File "/home/airflow/.local/lib/python3.7/site-packages/sqlalchemy/engine/base.py", line 1279, in execute
    future=False,
  File "/home/airflow/.local/lib/python3.7/site-packages/sqlalchemy/engine/base.py", line 1585, in _exec_driver_sql
    distilled_parameters,
  File "/home/airflow/.local/lib/python3.7/site-packages/sqlalchemy/engine/base.py", line 1846, in _execute_context
    e, statement, parameters, cursor, context
  File "/home/airflow/.local/lib/python3.7/site-packages/sqlalchemy/engine/base.py", line 2027, in _handle_dbapi_exception
    sqlalchemy_exception, with_traceback=exc_info[2], from_=e
  File "/home/airflow/.local/lib/python3.7/site-packages/sqlalchemy/util/compat.py", line 207, in raise_
    raise exception
  File "/home/airflow/.local/lib/python3.7/site-packages/sqlalchemy/engine/base.py", line 1803, in _execute_context
    cursor, statement, parameters, context
  File "/home/airflow/.local/lib/python3.7/site-packages/sqlalchemy/engine/default.py", line 719, in do_execute
    cursor.execute(statement, parameters)
sqlalchemy.exc.ProgrammingError: (psycopg2.errors.UndefinedTable) relation "car_assignment" does not exist
LINE 1: select * from car_assignment
                      ^

[SQL: select * from car_assignment]
(Background on this error at: https://sqlalche.me/e/14/f405)
[2023-12-24T17:08:45.171+0000] {taskinstance.py:1412} INFO - Marking task as FAILED. dag_id=example, task_id=fetching_data, execution_date=20231224T170844, start_date=20231224T170845, end_date=20231224T170845
[2023-12-24T17:08:45.177+0000] {standard_task_runner.py:97} ERROR - Failed to execute job 54 for task fetching_data ((psycopg2.errors.UndefinedTable) relation "car_assignment" does not exist
LINE 1: select * from car_assignment
                      ^

[SQL: select * from car_assignment]
(Background on this error at: https://sqlalche.me/e/14/f405); 224)
[2023-12-24T17:08:45.202+0000] {local_task_job.py:156} INFO - Task exited with return code 1
[2023-12-24T17:08:45.223+0000] {local_task_job.py:279} INFO - 0 downstream tasks scheduled from follow-on schedule check
