[2023-12-24T16:19:47.614+0000] {taskinstance.py:1171} INFO - Dependencies all met for <TaskInstance: example.fetching_data manual__2023-12-24T16:19:46.739484+00:00 [queued]>
[2023-12-24T16:19:47.618+0000] {taskinstance.py:1171} INFO - Dependencies all met for <TaskInstance: example.fetching_data manual__2023-12-24T16:19:46.739484+00:00 [queued]>
[2023-12-24T16:19:47.619+0000] {taskinstance.py:1368} INFO - 
--------------------------------------------------------------------------------
[2023-12-24T16:19:47.619+0000] {taskinstance.py:1369} INFO - Starting attempt 1 of 1
[2023-12-24T16:19:47.619+0000] {taskinstance.py:1370} INFO - 
--------------------------------------------------------------------------------
[2023-12-24T16:19:47.625+0000] {taskinstance.py:1389} INFO - Executing <Task(PythonOperator): fetching_data> on 2023-12-24 16:19:46.739484+00:00
[2023-12-24T16:19:47.633+0000] {standard_task_runner.py:52} INFO - Started process 800 to run task
[2023-12-24T16:19:47.636+0000] {standard_task_runner.py:79} INFO - Running: ['***', 'tasks', 'run', 'example', 'fetching_data', 'manual__2023-12-24T16:19:46.739484+00:00', '--job-id', '25', '--raw', '--subdir', 'DAGS_FOLDER/P2M3_saepul_hilal_DAG.py', '--cfg-path', '/tmp/tmp2u465jex', '--error-file', '/tmp/tmp51ikr44o']
[2023-12-24T16:19:47.637+0000] {standard_task_runner.py:80} INFO - Job 25: Subtask fetching_data
[2023-12-24T16:19:47.677+0000] {task_command.py:371} INFO - Running <TaskInstance: example.fetching_data manual__2023-12-24T16:19:46.739484+00:00 [running]> on host fb95896ee755
[2023-12-24T16:19:47.733+0000] {taskinstance.py:1583} INFO - Exporting the following env vars:
AIRFLOW_CTX_DAG_OWNER=saepul
AIRFLOW_CTX_DAG_ID=example
AIRFLOW_CTX_TASK_ID=fetching_data
AIRFLOW_CTX_EXECUTION_DATE=2023-12-24T16:19:46.739484+00:00
AIRFLOW_CTX_TRY_NUMBER=1
AIRFLOW_CTX_DAG_RUN_ID=manual__2023-12-24T16:19:46.739484+00:00
[2023-12-24T16:19:47.735+0000] {taskinstance.py:1902} ERROR - Task failed with exception
Traceback (most recent call last):
  File "/home/airflow/.local/lib/python3.7/site-packages/airflow/operators/python.py", line 171, in execute
    return_value = self.execute_callable()
  File "/home/airflow/.local/lib/python3.7/site-packages/airflow/operators/python.py", line 189, in execute_callable
    return self.python_callable(*self.op_args, **self.op_kwargs)
  File "/opt/airflow/dags/P2M3_saepul_hilal_DAG.py", line 18, in ambil_data
    conn=db.connect(conn_string)
  File "/home/airflow/.local/lib/python3.7/site-packages/psycopg2/__init__.py", line 122, in connect
    conn = _connect(dsn, connection_factory=connection_factory, **kwasync)
psycopg2.OperationalError: could not translate host name "localhost:8080" to address: Name or service not known

[2023-12-24T16:19:47.743+0000] {taskinstance.py:1412} INFO - Marking task as FAILED. dag_id=example, task_id=fetching_data, execution_date=20231224T161946, start_date=20231224T161947, end_date=20231224T161947
[2023-12-24T16:19:47.749+0000] {standard_task_runner.py:97} ERROR - Failed to execute job 25 for task fetching_data (could not translate host name "localhost:8080" to address: Name or service not known
; 800)
[2023-12-24T16:19:47.769+0000] {local_task_job.py:156} INFO - Task exited with return code 1
[2023-12-24T16:19:47.788+0000] {local_task_job.py:279} INFO - 0 downstream tasks scheduled from follow-on schedule check
