[2023-12-24T16:26:58.952+0000] {taskinstance.py:1171} INFO - Dependencies all met for <TaskInstance: example.fetching_data manual__2023-12-24T16:26:58.076116+00:00 [queued]>
[2023-12-24T16:26:58.958+0000] {taskinstance.py:1171} INFO - Dependencies all met for <TaskInstance: example.fetching_data manual__2023-12-24T16:26:58.076116+00:00 [queued]>
[2023-12-24T16:26:58.958+0000] {taskinstance.py:1368} INFO - 
--------------------------------------------------------------------------------
[2023-12-24T16:26:58.958+0000] {taskinstance.py:1369} INFO - Starting attempt 1 of 1
[2023-12-24T16:26:58.959+0000] {taskinstance.py:1370} INFO - 
--------------------------------------------------------------------------------
[2023-12-24T16:26:58.965+0000] {taskinstance.py:1389} INFO - Executing <Task(PythonOperator): fetching_data> on 2023-12-24 16:26:58.076116+00:00
[2023-12-24T16:26:58.970+0000] {standard_task_runner.py:52} INFO - Started process 917 to run task
[2023-12-24T16:26:58.972+0000] {standard_task_runner.py:79} INFO - Running: ['***', 'tasks', 'run', 'example', 'fetching_data', 'manual__2023-12-24T16:26:58.076116+00:00', '--job-id', '30', '--raw', '--subdir', 'DAGS_FOLDER/P2M3_saepul_hilal_DAG.py', '--cfg-path', '/tmp/tmphpf3t14x', '--error-file', '/tmp/tmp_gkqfpeb']
[2023-12-24T16:26:58.973+0000] {standard_task_runner.py:80} INFO - Job 30: Subtask fetching_data
[2023-12-24T16:26:59.010+0000] {task_command.py:371} INFO - Running <TaskInstance: example.fetching_data manual__2023-12-24T16:26:58.076116+00:00 [running]> on host fb95896ee755
[2023-12-24T16:26:59.064+0000] {taskinstance.py:1583} INFO - Exporting the following env vars:
AIRFLOW_CTX_DAG_OWNER=saepul
AIRFLOW_CTX_DAG_ID=example
AIRFLOW_CTX_TASK_ID=fetching_data
AIRFLOW_CTX_EXECUTION_DATE=2023-12-24T16:26:58.076116+00:00
AIRFLOW_CTX_TRY_NUMBER=1
AIRFLOW_CTX_DAG_RUN_ID=manual__2023-12-24T16:26:58.076116+00:00
[2023-12-24T16:26:59.069+0000] {taskinstance.py:1902} ERROR - Task failed with exception
Traceback (most recent call last):
  File "/home/airflow/.local/lib/python3.7/site-packages/pandas/io/sql.py", line 2056, in execute
    cur.execute(*args, **kwargs)
psycopg2.errors.UndefinedTable: relation "table_m3" does not exist
LINE 1: select * from table_m3
                      ^


The above exception was the direct cause of the following exception:

Traceback (most recent call last):
  File "/home/airflow/.local/lib/python3.7/site-packages/airflow/operators/python.py", line 171, in execute
    return_value = self.execute_callable()
  File "/home/airflow/.local/lib/python3.7/site-packages/airflow/operators/python.py", line 189, in execute_callable
    return self.python_callable(*self.op_args, **self.op_kwargs)
  File "/opt/airflow/dags/P2M3_saepul_hilal_DAG.py", line 22, in ambil_data
    df = pd.read_sql_query("select * from table_m3", conn)
  File "/home/airflow/.local/lib/python3.7/site-packages/pandas/io/sql.py", line 443, in read_sql_query
    dtype=dtype,
  File "/home/airflow/.local/lib/python3.7/site-packages/pandas/io/sql.py", line 2116, in read_query
    cursor = self.execute(*args)
  File "/home/airflow/.local/lib/python3.7/site-packages/pandas/io/sql.py", line 2068, in execute
    raise ex from exc
pandas.io.sql.DatabaseError: Execution failed on sql 'select * from table_m3': relation "table_m3" does not exist
LINE 1: select * from table_m3
                      ^

[2023-12-24T16:26:59.075+0000] {taskinstance.py:1412} INFO - Marking task as FAILED. dag_id=example, task_id=fetching_data, execution_date=20231224T162658, start_date=20231224T162658, end_date=20231224T162659
[2023-12-24T16:26:59.082+0000] {standard_task_runner.py:97} ERROR - Failed to execute job 30 for task fetching_data (Execution failed on sql 'select * from table_m3': relation "table_m3" does not exist
LINE 1: select * from table_m3
                      ^
; 917)
[2023-12-24T16:26:59.107+0000] {local_task_job.py:156} INFO - Task exited with return code 1
[2023-12-24T16:26:59.123+0000] {local_task_job.py:279} INFO - 0 downstream tasks scheduled from follow-on schedule check
